2021-09-19 11:03:15,867 - example_logger - ERROR - There was an exception in  main
Traceback (most recent call last):
  File "/home/subhomoy/Documents/Family-Tree-Generator/exception_decor.py", line 27, in wrapper
    return function(*args, **kwargs)
  File "main.py", line 144, in main
    tree = pkl.unpickle(pkl_file)
  File "main.py", line 17, in unpickle
    with open(f'pickles/{file}', "rb") as f :
FileNotFoundError: [Errno 2] No such file or directory: 'pickles/None'
2021-09-19 11:05:41,358 - example_logger - ERROR - There was an exception in  main
Traceback (most recent call last):
  File "/home/subhomoy/Documents/Family-Tree-Generator/exception_decor.py", line 27, in wrapper
    return function(*args, **kwargs)
  File "main.py", line 144, in main
    tree = pkl.unpickle(pkl_file)
  File "main.py", line 17, in unpickle
    with open(f'pickles/{file}', "rb") as f :
FileNotFoundError: [Errno 2] No such file or directory: 'pickles/None'
2021-09-19 11:07:47,724 - example_logger - ERROR - There was an exception in  main
Traceback (most recent call last):
  File "/home/subhomoy/Documents/Family-Tree-Generator/exception_decor.py", line 27, in wrapper
    return function(*args, **kwargs)
  File "main.py", line 137, in main
    sys.exit()
SystemExit
2021-09-19 11:24:06,718 - example_logger - ERROR - There was an exception in  main
Traceback (most recent call last):
  File "/home/subhomoy/Documents/Family-Tree-Generator/exception_decor.py", line 27, in wrapper
    return function(*args, **kwargs)
  File "main.py", line 137, in main
    sys.exit()
SystemExit
2021-09-19 11:24:29,929 - example_logger - ERROR - There was an exception in  main
Traceback (most recent call last):
  File "/home/subhomoy/Documents/Family-Tree-Generator/exception_decor.py", line 27, in wrapper
    return function(*args, **kwargs)
  File "main.py", line 137, in main
    sys.exit()
SystemExit
2021-09-19 11:27:30,118 - example_logger - ERROR - There was an exception in  main
Traceback (most recent call last):
  File "/home/subhomoy/Documents/Family-Tree-Generator/exception_decor.py", line 27, in wrapper
    return function(*args, **kwargs)
  File "main.py", line 114, in main
    query = intro_selection()
  File "main.py", line 45, in intro_selection
    return answers['intro']
KeyError: 'intro'
2021-09-19 11:27:37,903 - example_logger - ERROR - There was an exception in  main
Traceback (most recent call last):
  File "/home/subhomoy/Documents/Family-Tree-Generator/exception_decor.py", line 27, in wrapper
    return function(*args, **kwargs)
  File "main.py", line 114, in main
    query = intro_selection()
  File "main.py", line 45, in intro_selection
    return answers['intro']
KeyError: 'intro'
2021-09-19 11:28:58,472 - example_logger - ERROR - There was an exception in  main
Traceback (most recent call last):
  File "/home/subhomoy/Documents/Family-Tree-Generator/exception_decor.py", line 27, in wrapper
    return function(*args, **kwargs)
  File "main.py", line 116, in main
    sys.exit()
SystemExit
2021-09-19 14:37:22,381 - example_logger - ERROR - There was an exception in  main
Traceback (most recent call last):
  File "/home/subhomoy/Documents/Family-Tree-Generator/exception_decor.py", line 27, in wrapper
    return function(*args, **kwargs)
  File "main.py", line 119, in main
    query = intro_selection()
  File "main.py", line 45, in intro_selection
    return answers['intro']
KeyError: 'intro'
2021-09-19 14:38:01,592 - example_logger - ERROR - There was an exception in  main
Traceback (most recent call last):
  File "/home/subhomoy/Documents/Family-Tree-Generator/exception_decor.py", line 27, in wrapper
    return function(*args, **kwargs)
  File "main.py", line 121, in main
    sys.exit()
SystemExit
2021-09-19 14:38:45,969 - example_logger - ERROR - There was an exception in  main
Traceback (most recent call last):
  File "/home/subhomoy/Documents/Family-Tree-Generator/exception_decor.py", line 27, in wrapper
    return function(*args, **kwargs)
  File "main.py", line 121, in main
    sys.exit()
SystemExit
2021-09-19 14:41:25,201 - example_logger - ERROR - There was an exception in  main
Traceback (most recent call last):
  File "/home/subhomoy/Documents/Family-Tree-Generator/exception_decor.py", line 27, in wrapper
    return function(*args, **kwargs)
  File "main.py", line 131, in main
    num,name,generation,parent = insert_member_input()
  File "main.py", line 87, in insert_member_input
    mamber_input_int,member_input_name = input("Enter the root element ").split(",")
KeyboardInterrupt
2021-09-19 14:42:50,303 - example_logger - ERROR - There was an exception in  main
Traceback (most recent call last):
  File "/home/subhomoy/Documents/Family-Tree-Generator/exception_decor.py", line 27, in wrapper
    return function(*args, **kwargs)
  File "main.py", line 132, in main
    tree.find_member_by_name_generation_DFS(tree,parent,generation).insert_member(num,name)
  File "/home/subhomoy/Documents/Family-Tree-Generator/family_tree.py", line 18, in find_member_by_name_generation_DFS
    self.finder_by_name_generation(tree,name,generation)
  File "/home/subhomoy/Documents/Family-Tree-Generator/family_tree.py", line 29, in finder_by_name_generation
    self.finder(i,value)
NameError: name 'value' is not defined
2021-09-19 14:44:54,268 - example_logger - ERROR - There was an exception in  main
Traceback (most recent call last):
  File "/home/subhomoy/Documents/Family-Tree-Generator/exception_decor.py", line 27, in wrapper
    return function(*args, **kwargs)
  File "main.py", line 122, in main
    sys.exit()
SystemExit
2021-09-19 14:49:44,483 - example_logger - ERROR - There was an exception in  main
Traceback (most recent call last):
  File "/home/subhomoy/Documents/Family-Tree-Generator/exception_decor.py", line 27, in wrapper
    return function(*args, **kwargs)
  File "main.py", line 132, in main
    tree.find_member_by_name_generation_DFS(tree,parent,generation).insert_member(num,name)
AttributeError: 'NoneType' object has no attribute 'insert_member'
2021-09-19 14:52:49,128 - example_logger - ERROR - There was an exception in  main
Traceback (most recent call last):
  File "/home/subhomoy/Documents/Family-Tree-Generator/exception_decor.py", line 27, in wrapper
    return function(*args, **kwargs)
  File "main.py", line 122, in main
    sys.exit()
SystemExit
2021-09-19 14:54:40,875 - example_logger - ERROR - There was an exception in  main
Traceback (most recent call last):
  File "/home/subhomoy/Documents/Family-Tree-Generator/exception_decor.py", line 27, in wrapper
    return function(*args, **kwargs)
  File "main.py", line 120, in main
    query = intro_selection()
  File "main.py", line 45, in intro_selection
    return answers['intro']
KeyError: 'intro'
2021-09-19 14:55:11,626 - example_logger - ERROR - There was an exception in  main
Traceback (most recent call last):
  File "/home/subhomoy/Documents/Family-Tree-Generator/exception_decor.py", line 27, in wrapper
    return function(*args, **kwargs)
  File "main.py", line 122, in main
    sys.exit()
SystemExit
2021-09-19 14:56:31,293 - example_logger - ERROR - There was an exception in  main
Traceback (most recent call last):
  File "/home/subhomoy/Documents/Family-Tree-Generator/exception_decor.py", line 27, in wrapper
    return function(*args, **kwargs)
  File "main.py", line 122, in main
    sys.exit()
SystemExit
2021-09-19 14:58:36,505 - example_logger - ERROR - There was an exception in  main
Traceback (most recent call last):
  File "/home/subhomoy/Documents/Family-Tree-Generator/exception_decor.py", line 27, in wrapper
    return function(*args, **kwargs)
  File "main.py", line 122, in main
    sys.exit()
SystemExit
2021-09-19 14:59:52,636 - example_logger - ERROR - There was an exception in  main
Traceback (most recent call last):
  File "/home/subhomoy/Documents/Family-Tree-Generator/exception_decor.py", line 27, in wrapper
    return function(*args, **kwargs)
  File "main.py", line 122, in main
    sys.exit()
SystemExit
2021-09-19 15:00:27,357 - example_logger - ERROR - There was an exception in  main
Traceback (most recent call last):
  File "/home/subhomoy/Documents/Family-Tree-Generator/exception_decor.py", line 27, in wrapper
    return function(*args, **kwargs)
  File "main.py", line 122, in main
    sys.exit()
SystemExit
2021-09-19 15:08:15,312 - example_logger - ERROR - There was an exception in  main
Traceback (most recent call last):
  File "/home/subhomoy/Documents/Family-Tree-Generator/exception_decor.py", line 27, in wrapper
    return function(*args, **kwargs)
  File "main.py", line 108, in main
    check_pkl = check_pickle(pkl,pkl_file=None)
  File "main.py", line 78, in check_pickle
    pkl_file = answers[name]
KeyError: 'pickle_list'
2021-09-19 15:08:43,446 - example_logger - ERROR - There was an exception in  main
Traceback (most recent call last):
  File "/home/subhomoy/Documents/Family-Tree-Generator/exception_decor.py", line 27, in wrapper
    return function(*args, **kwargs)
  File "main.py", line 122, in main
    sys.exit()
SystemExit
2021-09-19 18:25:10,978 - example_logger - ERROR - There was an exception in  main
Traceback (most recent call last):
  File "/home/subhomoy/Documents/Family-Tree-Generator/exception_decor.py", line 28, in wrapper
    return function(*args, **kwargs)
  File "main.py", line 146, in main
    console(tree)
  File "main.py", line 73, in console
    decode_command(query_cmd)
NameError: name 'decode_command' is not defined
2021-09-19 18:25:54,575 - example_logger - ERROR - There was an exception in  main
Traceback (most recent call last):
  File "/home/subhomoy/Documents/Family-Tree-Generator/exception_decor.py", line 28, in wrapper
    return function(*args, **kwargs)
  File "main.py", line 146, in main
    console(tree)
  File "main.py", line 73, in console
    decode_command_show_table(query_cmd)
  File "main.py", line 16, in wrapper
    result.append(item.find(r"[a-z]{1,},.[0-9]*",args[0]).split(','))
TypeError: slice indices must be integers or None or have an __index__ method
2021-09-19 18:26:57,501 - example_logger - ERROR - There was an exception in  main
Traceback (most recent call last):
  File "/home/subhomoy/Documents/Family-Tree-Generator/exception_decor.py", line 28, in wrapper
    return function(*args, **kwargs)
  File "main.py", line 148, in main
    console(tree)
  File "main.py", line 75, in console
    decode_command_show_table(query_cmd)
  File "main.py", line 16, in wrapper
    item = item.find(r"[a-z]{1,},.[0-9]*",args[0])
TypeError: slice indices must be integers or None or have an __index__ method
2021-09-19 18:28:52,641 - example_logger - ERROR - There was an exception in  main
Traceback (most recent call last):
  File "/home/subhomoy/Documents/Family-Tree-Generator/exception_decor.py", line 28, in wrapper
    return function(*args, **kwargs)
  File "main.py", line 149, in main
    console(tree)
  File "main.py", line 76, in console
    decode_command_show_table(query_cmd)
  File "main.py", line 17, in wrapper
    item = item.find(r"[a-z]{1,},.[0-9]*",args[0])
TypeError: slice indices must be integers or None or have an __index__ method
2021-09-19 18:31:14,093 - example_logger - ERROR - There was an exception in  main
Traceback (most recent call last):
  File "/home/subhomoy/Documents/Family-Tree-Generator/exception_decor.py", line 28, in wrapper
    return function(*args, **kwargs)
  File "main.py", line 148, in main
    console(tree)
  File "main.py", line 75, in console
    decode_command_show_table(query_cmd)
  File "main.py", line 16, in wrapper
    item = item.find(r"[a-z]{1,},.[0-9]*",args[0])
TypeError: slice indices must be integers or None or have an __index__ method
2021-09-19 18:32:35,904 - example_logger - ERROR - There was an exception in  main
Traceback (most recent call last):
  File "/home/subhomoy/Documents/Family-Tree-Generator/exception_decor.py", line 28, in wrapper
    return function(*args, **kwargs)
  File "main.py", line 148, in main
    console(tree)
  File "main.py", line 75, in console
    decode_command_show_table(query_cmd)
  File "main.py", line 16, in wrapper
    item = item.search(r"[a-z]{1,},.[0-9]*",args[0])
AttributeError: 'str' object has no attribute 'search'
2021-09-19 18:33:06,774 - example_logger - ERROR - There was an exception in  main
Traceback (most recent call last):
  File "/home/subhomoy/Documents/Family-Tree-Generator/exception_decor.py", line 28, in wrapper
    return function(*args, **kwargs)
  File "main.py", line 148, in main
    console(tree)
  File "main.py", line 75, in console
    decode_command_show_table(query_cmd)
  File "main.py", line 18, in wrapper
    result.append(item.split(','))
AttributeError: 're.Match' object has no attribute 'split'
2021-09-19 18:35:40,284 - example_logger - ERROR - There was an exception in  main
Traceback (most recent call last):
  File "/home/subhomoy/Documents/Family-Tree-Generator/exception_decor.py", line 28, in wrapper
    return function(*args, **kwargs)
  File "main.py", line 148, in main
    console(tree)
  File "main.py", line 75, in console
    decode_command_show_table(query_cmd)
  File "main.py", line 17, in wrapper
    print('ksanf',item.string())
TypeError: 'str' object is not callable
2021-09-19 18:36:45,709 - example_logger - ERROR - There was an exception in  main
Traceback (most recent call last):
  File "/home/subhomoy/Documents/Family-Tree-Generator/exception_decor.py", line 28, in wrapper
    return function(*args, **kwargs)
  File "main.py", line 148, in main
    console(tree)
  File "main.py", line 75, in console
    decode_command_show_table(query_cmd)
  File "main.py", line 18, in wrapper
    result.append(item.split(','))
AttributeError: 're.Match' object has no attribute 'split'
2021-09-19 18:39:45,610 - example_logger - ERROR - There was an exception in  main
Traceback (most recent call last):
  File "/home/subhomoy/Documents/Family-Tree-Generator/exception_decor.py", line 28, in wrapper
    return function(*args, **kwargs)
  File "main.py", line 148, in main
    console(tree)
  File "main.py", line 75, in console
    decode_command_show_table(query_cmd)
  File "main.py", line 21, in wrapper
    return func(results)
NameError: name 'results' is not defined
2021-09-19 18:41:55,387 - example_logger - ERROR - There was an exception in  main
Traceback (most recent call last):
  File "/home/subhomoy/Documents/Family-Tree-Generator/exception_decor.py", line 28, in wrapper
    return function(*args, **kwargs)
  File "main.py", line 146, in main
    elif query == "console":
SystemExit
2021-09-19 19:07:46,613 - example_logger - ERROR - There was an exception in  main
Traceback (most recent call last):
  File "/home/subhomoy/Documents/Family-Tree-Generator/exception_decor.py", line 28, in wrapper
    return function(*args, **kwargs)
  File "main.py", line 145, in main
    sys.exit()
SystemExit
2021-09-19 19:31:10,204 - example_logger - ERROR - There was an exception in  main
Traceback (most recent call last):
  File "/home/subhomoy/Documents/Family-Tree-Generator/exception_decor.py", line 28, in wrapper
    return function(*args, **kwargs)
  File "main.py", line 149, in main
    console(tree)
  File "main.py", line 74, in console
    decode_command_show_table(query_cmd)
  File "main.py", line 20, in wrapper
    return func(result)
  File "main.py", line 82, in decode_command_show_table
    sub_tree = tree.find_member_by_name_generation_DFS(tree,parent,generation)
NameError: name 'tree' is not defined
2021-09-19 19:32:43,045 - example_logger - ERROR - There was an exception in  main
Traceback (most recent call last):
  File "/home/subhomoy/Documents/Family-Tree-Generator/exception_decor.py", line 28, in wrapper
    return function(*args, **kwargs)
  File "main.py", line 149, in main
    console(tree)
  File "main.py", line 74, in console
    decode_command_show_table(query_cmd,tree)
  File "main.py", line 20, in wrapper
    return func(result)
TypeError: decode_command_show_table() missing 1 required positional argument: 'tree'
2021-09-19 19:35:07,433 - example_logger - ERROR - There was an exception in  main
Traceback (most recent call last):
  File "/home/subhomoy/Documents/Family-Tree-Generator/exception_decor.py", line 28, in wrapper
    return function(*args, **kwargs)
  File "main.py", line 149, in main
    console(tree)
  File "main.py", line 73, in console
    name,generation=decode_command_show_table(query_cmd,tree)
  File "main.py", line 19, in wrapper
    return func(result)
TypeError: decode_command_show_table() missing 1 required positional argument: 'tree'
2021-09-19 19:35:52,745 - example_logger - ERROR - There was an exception in  main
Traceback (most recent call last):
  File "/home/subhomoy/Documents/Family-Tree-Generator/exception_decor.py", line 28, in wrapper
    return function(*args, **kwargs)
  File "main.py", line 149, in main
    console(tree)
  File "main.py", line 74, in console
    sub_tree = tree.find_member_by_name_generation_DFS(tree,parent,generation)
NameError: name 'parent' is not defined
2021-09-19 19:37:15,849 - example_logger - ERROR - There was an exception in  main
Traceback (most recent call last):
  File "/home/subhomoy/Documents/Family-Tree-Generator/exception_decor.py", line 28, in wrapper
    return function(*args, **kwargs)
  File "main.py", line 149, in main
    console(tree)
  File "main.py", line 73, in console
    parent,generation=decode_command_show_table(query_cmd)
ValueError: too many values to unpack (expected 2)
2021-09-19 19:38:14,675 - example_logger - ERROR - There was an exception in  main
Traceback (most recent call last):
  File "/home/subhomoy/Documents/Family-Tree-Generator/exception_decor.py", line 28, in wrapper
    return function(*args, **kwargs)
  File "main.py", line 149, in main
    console(tree)
  File "main.py", line 73, in console
    parent,generation=decode_command_show_table(query_cmd)
ValueError: too many values to unpack (expected 2)
2021-09-19 19:38:55,988 - example_logger - ERROR - There was an exception in  main
Traceback (most recent call last):
  File "/home/subhomoy/Documents/Family-Tree-Generator/exception_decor.py", line 28, in wrapper
    return function(*args, **kwargs)
  File "main.py", line 150, in main
    console(tree)
  File "main.py", line 74, in console
    parent,generation=decode_command_show_table(query_cmd)
ValueError: too many values to unpack (expected 2)
2021-09-19 19:39:40,756 - example_logger - ERROR - There was an exception in  main
Traceback (most recent call last):
  File "/home/subhomoy/Documents/Family-Tree-Generator/exception_decor.py", line 28, in wrapper
    return function(*args, **kwargs)
  File "main.py", line 150, in main
    console(tree)
  File "main.py", line 74, in console
    parent,generation=decode_command_show_table(query_cmd)
ValueError: too many values to unpack (expected 2)
2021-09-19 19:42:21,542 - example_logger - ERROR - There was an exception in  main
Traceback (most recent call last):
  File "/home/subhomoy/Documents/Family-Tree-Generator/exception_decor.py", line 28, in wrapper
    return function(*args, **kwargs)
  File "main.py", line 150, in main
    console(tree)
  File "main.py", line 75, in console
    sub_tree = tree.find_member_by_name_generation_DFS(tree,parent,generation)
  File "/home/subhomoy/Documents/Family-Tree-Generator/family_tree.py", line 18, in find_member_by_name_generation_DFS
    self.finder_by_name_generation(tree,name,generation)
  File "/home/subhomoy/Documents/Family-Tree-Generator/family_tree.py", line 29, in finder_by_name_generation
    self.finder_by_name_generation(i,name,generation=generation+1)
TypeError: can only concatenate str (not "int") to str
2021-09-19 19:43:13,672 - example_logger - ERROR - There was an exception in  main
Traceback (most recent call last):
  File "/home/subhomoy/Documents/Family-Tree-Generator/exception_decor.py", line 28, in wrapper
    return function(*args, **kwargs)
  File "main.py", line 150, in main
    console(tree)
  File "main.py", line 74, in console
    parent,generation=decode_command_show_table(query_cmd)
ValueError: too many values to unpack (expected 2)
2021-09-19 19:43:33,744 - example_logger - ERROR - There was an exception in  main
Traceback (most recent call last):
  File "/home/subhomoy/Documents/Family-Tree-Generator/exception_decor.py", line 28, in wrapper
    return function(*args, **kwargs)
  File "main.py", line 150, in main
    console(tree)
  File "main.py", line 75, in console
    sub_tree = tree.find_member_by_name_generation_DFS(tree,parent,generation)
  File "/home/subhomoy/Documents/Family-Tree-Generator/family_tree.py", line 18, in find_member_by_name_generation_DFS
    self.finder_by_name_generation(tree,name,generation)
  File "/home/subhomoy/Documents/Family-Tree-Generator/family_tree.py", line 29, in finder_by_name_generation
    self.finder_by_name_generation(i,name,generation=generation+1)
TypeError: can only concatenate str (not "int") to str
2021-09-19 19:45:30,893 - example_logger - ERROR - There was an exception in  main
Traceback (most recent call last):
  File "/home/subhomoy/Documents/Family-Tree-Generator/exception_decor.py", line 28, in wrapper
    return function(*args, **kwargs)
  File "main.py", line 150, in main
    console(tree)
  File "main.py", line 76, in console
    sub_tree.structure(sub_tree)
AttributeError: 'NoneType' object has no attribute 'structure'
2021-09-19 19:46:25,332 - example_logger - ERROR - There was an exception in  main
Traceback (most recent call last):
  File "/home/subhomoy/Documents/Family-Tree-Generator/exception_decor.py", line 28, in wrapper
    return function(*args, **kwargs)
  File "main.py", line 151, in main
    console(tree)
  File "main.py", line 77, in console
    sub_tree.structure(sub_tree)
AttributeError: 'NoneType' object has no attribute 'structure'
2021-09-20 09:31:07,299 - example_logger - ERROR - There was an exception in  main
Traceback (most recent call last):
  File "/home/subhomoy/Documents/Family-Tree-Generator/exception_decor.py", line 28, in wrapper
    return function(*args, **kwargs)
  File "main.py", line 149, in main
    sys.exit()
SystemExit
2021-09-20 09:32:13,551 - example_logger - ERROR - There was an exception in  main
Traceback (most recent call last):
  File "/home/subhomoy/Documents/Family-Tree-Generator/exception_decor.py", line 28, in wrapper
    return function(*args, **kwargs)
  File "main.py", line 151, in main
    console(tree)
  File "main.py", line 77, in console
    sub_tree.structure(sub_tree)
AttributeError: 'NoneType' object has no attribute 'structure'
2021-09-20 09:34:51,363 - example_logger - ERROR - There was an exception in  main
Traceback (most recent call last):
  File "/home/subhomoy/Documents/Family-Tree-Generator/exception_decor.py", line 28, in wrapper
    return function(*args, **kwargs)
  File "main.py", line 151, in main
    console(tree)
  File "main.py", line 77, in console
    sub_tree.structure(sub_tree)
AttributeError: 'NoneType' object has no attribute 'structure'
2021-09-20 09:36:41,147 - example_logger - ERROR - There was an exception in  main
Traceback (most recent call last):
  File "/home/subhomoy/Documents/Family-Tree-Generator/exception_decor.py", line 28, in wrapper
    return function(*args, **kwargs)
  File "main.py", line 151, in main
    console(tree)
  File "main.py", line 75, in console
    sub_tree = tree.find_member_by_name_generation_DFS(tree,parent,generation)
  File "/home/subhomoy/Documents/Family-Tree-Generator/family_tree.py", line 19, in find_member_by_name_generation_DFS
    print(self.key.name)
AttributeError: 'NoneType' object has no attribute 'name'
2021-09-20 09:38:54,601 - example_logger - ERROR - There was an exception in  main
Traceback (most recent call last):
  File "/home/subhomoy/Documents/Family-Tree-Generator/exception_decor.py", line 28, in wrapper
    return function(*args, **kwargs)
  File "main.py", line 150, in main
    console(tree)
  File "main.py", line 75, in console
    sub_tree.structure(sub_tree)
AttributeError: 'NoneType' object has no attribute 'structure'
2021-09-20 09:39:33,467 - example_logger - ERROR - There was an exception in  main
Traceback (most recent call last):
  File "/home/subhomoy/Documents/Family-Tree-Generator/exception_decor.py", line 28, in wrapper
    return function(*args, **kwargs)
  File "main.py", line 150, in main
    console(tree)
  File "main.py", line 75, in console
    sub_tree.structure(sub_tree)
AttributeError: 'NoneType' object has no attribute 'structure'
2021-09-20 09:40:52,440 - example_logger - ERROR - There was an exception in  main
Traceback (most recent call last):
  File "/home/subhomoy/Documents/Family-Tree-Generator/exception_decor.py", line 28, in wrapper
    return function(*args, **kwargs)
  File "main.py", line 150, in main
    console(tree)
  File "main.py", line 75, in console
    sub_tree.structure(sub_tree)
AttributeError: 'NoneType' object has no attribute 'structure'
2021-09-20 09:41:15,457 - example_logger - ERROR - There was an exception in  main
Traceback (most recent call last):
  File "/home/subhomoy/Documents/Family-Tree-Generator/exception_decor.py", line 28, in wrapper
    return function(*args, **kwargs)
  File "main.py", line 150, in main
    console(tree)
  File "main.py", line 75, in console
    sub_tree.structure(sub_tree)
AttributeError: 'NoneType' object has no attribute 'structure'
2021-09-20 09:42:17,973 - example_logger - ERROR - There was an exception in  main
Traceback (most recent call last):
  File "/home/subhomoy/Documents/Family-Tree-Generator/exception_decor.py", line 28, in wrapper
    return function(*args, **kwargs)
  File "main.py", line 149, in main
    console(tree)
  File "main.py", line 75, in console
    sub_tree.structure(sub_tree)
AttributeError: 'NoneType' object has no attribute 'structure'
2021-09-20 09:45:00,284 - example_logger - ERROR - There was an exception in  main
Traceback (most recent call last):
  File "/home/subhomoy/Documents/Family-Tree-Generator/exception_decor.py", line 28, in wrapper
    return function(*args, **kwargs)
  File "main.py", line 147, in main
    query = intro_selection()
SystemExit
2021-09-20 09:45:52,127 - example_logger - ERROR - There was an exception in  main
Traceback (most recent call last):
  File "/home/subhomoy/Documents/Family-Tree-Generator/exception_decor.py", line 28, in wrapper
    return function(*args, **kwargs)
  File "main.py", line 149, in main
    sys.exit()
SystemExit
2021-09-20 10:41:25,516 - example_logger - ERROR - There was an exception in  main
Traceback (most recent call last):
  File "/home/subhomoy/Documents/Family-Tree-Generator/exception_decor.py", line 28, in wrapper
    return function(*args, **kwargs)
  File "main.py", line 182, in main
    sys.exit()
SystemExit
2021-09-20 11:12:29,027 - example_logger - ERROR - There was an exception in  main
Traceback (most recent call last):
  File "/home/subhomoy/Documents/Family-Tree-Generator/exception_decor.py", line 28, in wrapper
    return function(*args, **kwargs)
  File "main.py", line 230, in main
    sys.exit()
SystemExit
2021-09-20 11:12:58,204 - example_logger - ERROR - There was an exception in  main
Traceback (most recent call last):
  File "/home/subhomoy/Documents/Family-Tree-Generator/exception_decor.py", line 28, in wrapper
    return function(*args, **kwargs)
  File "main.py", line 230, in main
    sys.exit()
SystemExit
